Traceback (most recent call last):
  File "/home/zhanghc@1/888_second_work/0.second/pytracking-master/pytracking/VOT/dimp50.py", line 8, in <module>
    os.execv(sys.argv[0], sys.argv)
NameError: name 'sys' is not defined

During handling of the above exception, another exception occurred:

Traceback (most recent call last):
  File "/home/zhanghc@1/anaconda3/envs/pytracking/lib/python3.7/runpy.py", line 193, in _run_module_as_main
    "__main__", mod_spec)
  File "/home/zhanghc@1/anaconda3/envs/pytracking/lib/python3.7/runpy.py", line 85, in _run_code
    exec(code, run_globals)
  File "/home/zhanghc@1/888_second_work/0.second/pytracking-master/pytracking/VOT/dimp50.py", line 10, in <module>
    sys.exit('EXCEPTION: Failed to Execute under modified environment, '+e)
NameError: name 'sys' is not defined
Process not alive anymore, unable to retrieve return code
